Workbook

Sheet PLAN
A1: Self-Reliance Plan
A2: Expanded working version of the Self-Reliance Plan form (PD60007387). Fill in the yellow cells. Steps 2 (income & expenses) are on the Income, Expenses, and Debts tabs; results are on the Summary tab.
A4: Member Information
A5: Name
A6: Phone / email
A7: Address
A8: Date of review
A9: Reviewed with (leader)
A11: Household members
A12: Name | B12: Relationship | C12: Age | D12: Employment / school status | E12: Health or special needs | F12: Notes
A22: Step 1: What are my needs?
A23: Immediate needs (food, clothing, medical/emotional care, housing)
A24: Longer-term needs (education, improved employment)
A26: Step 2: What are my income and expenses? → see Income, Expenses, Debts, and Summary tabs
A28: Step 3: What other resources are available?
A29: Individual resources and skills
A30: Help available from family members
A31: Relevant community resources
A33: Step 4: What is my personal or family plan to become more self-reliant?
A34: Consider participating in a self-reliance group.
A35: Resources and skills needed | C35: Steps to be taken | F35: By when
A43: Step 5: What work or service will I contribute in return for any assistance I may receive?
A44: Ideas to share with the bishop or branch president
A45: Work or service assignment (after consulting with bishop)
A47: Commitment
A48: Member's signature | E48: Date
A49: Spouse's signature | E49: Date

Sheet SUMMARY
A1: Financial Summary
A2: Everything on this tab calculates from the Income, Expenses, and Debts tabs — no entry needed. Use the bottom section to copy totals onto the official Self-Reliance Plan form.
A4: Key Figures | B4: Monthly | C4: Notes
A5: Total monthly income | B5: =INCOME!F42
A6: Total monthly expenses | B6: =EXPENSES!E128
A7: Monthly surplus / (shortfall) | B7: =B5-B6 | C7: Negative = spending more than comes in
A8: Discretionary expenses (could be reduced) | B8: =SUMIFS(EXPENSES!E5:E126,EXPENSES!F5:F126,"Discretionary") | C8: Rows marked Discretionary on Expenses tab
A9: Surplus / (shortfall) if discretionary cut | B9: =B7+B8
A10: Essential expenses only | B10: =SUMIFS(EXPENSES!E5:E126,EXPENSES!F5:F126,"Essential") | C10: Bare-minimum monthly need
A12: Debt & Risk Indicators | B12: Value | C12: Guideline
A13: Total past-due amount (bills + debts) | B13: =EXPENSES!I128 | C13: Urgent — address first
A14: Total debt balance owed | B14: =DEBTS!C21
A15: Housing cost as % of income | B15: =IFERROR(SUMIFS(EXPENSES!E5:E126,EXPENSES!A5:A126,"Housing")/B5,0) | C15: Under 30% is generally considered affordable
A16: Debt payments as % of income | B16: =IFERROR(DEBTS!E21/B5,0) | C16: Over 20% (excl. housing & car) signals strain
A17: Income-to-expense ratio | B17: =IFERROR(B5/B6,0) | C17: Below 1.00 = income doesn't cover expenses
A19: Expenses by Category | B19: Monthly | C19: % of Expenses | D19: Past Due
A20: Tithes & Offerings | B20: =SUMIFS(EXPENSES!$E$5:$E$126,EXPENSES!$A$5:$A$126,A20) | C20: =IFERROR(B20/$B$6,0) | D20: =SUMIFS(EXPENSES!$I$5:$I$126,EXPENSES!$A$5:$A$126,A20)
A21: Housing | B21: =SUMIFS(EXPENSES!$E$5:$E$126,EXPENSES!$A$5:$A$126,A21) | C21: =IFERROR(B21/$B$6,0) | D21: =SUMIFS(EXPENSES!$I$5:$I$126,EXPENSES!$A$5:$A$126,A21)
A22: Utilities | B22: =SUMIFS(EXPENSES!$E$5:$E$126,EXPENSES!$A$5:$A$126,A22) | C22: =IFERROR(B22/$B$6,0) | D22: =SUMIFS(EXPENSES!$I$5:$I$126,EXPENSES!$A$5:$A$126,A22)
A23: Food | B23: =SUMIFS(EXPENSES!$E$5:$E$126,EXPENSES!$A$5:$A$126,A23) | C23: =IFERROR(B23/$B$6,0) | D23: =SUMIFS(EXPENSES!$I$5:$I$126,EXPENSES!$A$5:$A$126,A23)
A24: Household & Personal | B24: =SUMIFS(EXPENSES!$E$5:$E$126,EXPENSES!$A$5:$A$126,A24) | C24: =IFERROR(B24/$B$6,0) | D24: =SUMIFS(EXPENSES!$I$5:$I$126,EXPENSES!$A$5:$A$126,A24)
A25: Clothing | B25: =SUMIFS(EXPENSES!$E$5:$E$126,EXPENSES!$A$5:$A$126,A25) | C25: =IFERROR(B25/$B$6,0) | D25: =SUMIFS(EXPENSES!$I$5:$I$126,EXPENSES!$A$5:$A$126,A25)
A26: Transportation | B26: =SUMIFS(EXPENSES!$E$5:$E$126,EXPENSES!$A$5:$A$126,A26) | C26: =IFERROR(B26/$B$6,0) | D26: =SUMIFS(EXPENSES!$I$5:$I$126,EXPENSES!$A$5:$A$126,A26)
A27: Medical & Health | B27: =SUMIFS(EXPENSES!$E$5:$E$126,EXPENSES!$A$5:$A$126,A27) | C27: =IFERROR(B27/$B$6,0) | D27: =SUMIFS(EXPENSES!$I$5:$I$126,EXPENSES!$A$5:$A$126,A27)
A28: Childcare & Dependents | B28: =SUMIFS(EXPENSES!$E$5:$E$126,EXPENSES!$A$5:$A$126,A28) | C28: =IFERROR(B28/$B$6,0) | D28: =SUMIFS(EXPENSES!$I$5:$I$126,EXPENSES!$A$5:$A$126,A28)
A29: Education | B29: =SUMIFS(EXPENSES!$E$5:$E$126,EXPENSES!$A$5:$A$126,A29) | C29: =IFERROR(B29/$B$6,0) | D29: =SUMIFS(EXPENSES!$I$5:$I$126,EXPENSES!$A$5:$A$126,A29)
A30: Debt Payments | B30: =SUMIFS(EXPENSES!$E$5:$E$126,EXPENSES!$A$5:$A$126,A30) | C30: =IFERROR(B30/$B$6,0) | D30: =SUMIFS(EXPENSES!$I$5:$I$126,EXPENSES!$A$5:$A$126,A30)
A31: Legal & Government | B31: =SUMIFS(EXPENSES!$E$5:$E$126,EXPENSES!$A$5:$A$126,A31) | C31: =IFERROR(B31/$B$6,0) | D31: =SUMIFS(EXPENSES!$I$5:$I$126,EXPENSES!$A$5:$A$126,A31)
... A36: Irregular / Annual Costs | B36: =SUMIFS(EXPENSES!$E$5:$E$126,EXPENSES!$A$5:$A$126,A36) | C36: =IFERROR(B36/$B$6,0) | D36: =SUMIFS(EXPENSES!$I$5:$I$126,EXPENSES!$A$5:$A$126,A36)
A37: Total | B37: =SUM(B20:B36) | C37: =IFERROR(B37/$B$6,0) | D37: =SUM(D20:D36)
A39: Transfer to Official SRP Form — Income | B39: Monthly
A40: Income from all household members | B40: =SUMIFS(INCOME!$F$5:$F$40,INCOME!$G$5:$G$40,A40)
A41: Other financial sources (family, others) | B41: =SUMIFS(INCOME!$F$5:$F$40,INCOME!$G$5:$G$40,A41)
A42: Government assistance | B42: =SUMIFS(INCOME!$F$5:$F$40,INCOME!$G$5:$G$40,A42)
A43: Total | B43: =SUM(B40:B42)
A45: Transfer to Official SRP Form — Expenses | B45: Monthly
A46: Tithes, offerings | B46: =SUMIFS(EXPENSES!$E$5:$E$126,EXPENSES!$J$5:$J$126,A46)
A47: Food | B47: =SUMIFS(EXPENSES!$E$5:$E$126,EXPENSES!$J$5:$J$126,A47)
A48: Housing | B48: =SUMIFS(EXPENSES!$E$5:$E$126,EXPENSES!$J$5:$J$126,A48)
A49: Water | B49: =SUMIFS(EXPENSES!$E$5:$E$126,EXPENSES!$J$5:$J$126,A49)
...

Sheet INCOME
A1: Monthly Income
A2: Fill in the yellow cells only (blue text). Choose Frequency from the dropdown — the Monthly column converts automatically (e.g. Groceries $150 Weekly → $650.00/mo). Rename any 'Other' row to fit. Grey columns calculate on their own. Include every household member's income. Use take-home (net) pay.
A4: Category | B4: Source | C4: Household Member | D4: Amount | E4: Frequency | F4: Monthly | G4: SRP Form Line | H4: Notes
B5: EARNED INCOME | F5: =SUM(F6:F12)
A6: Earned Income | B6: Wages — primary earner | E6: Monthly | F6: =IF(D6="",0,D6*IFERROR(INDEX(LISTS!$B$2:$B$8,MATCH(E6,LISTS!$A$2:$A$8,0)),1)) | G6: Income from all household members
A7: Earned Income | B7: Wages — spouse | E7: Monthly | F7: =IF(D7="",0,D7*IFERROR(INDEX(LISTS!$B$2:$B$8,MATCH(E7,LISTS!$A$2:$A$8,0)),1)) | G7: Income from all household members
A8: Earned Income | B8: Wages — other household members | E8: Monthly | F8: =IF(D8="",0,D8*IFERROR(INDEX(LISTS!$B$2:$B$8,MATCH(E8,LISTS!$A$2:$A$8,0)),1)) | G8: Income from all household members
A9: Earned Income | B9: Tips / commissions / overtime | E9: Monthly | F9: =IF(D9="",0,D9*IFERROR(INDEX(LISTS!$B$2:$B$8,MATCH(E9,LISTS!$A$2:$A$8,0)),1)) | G9: Income from all household members
A10: Earned Income | B10: Self-employment / gig work (net) | E10: Monthly | F10: =IF(D10="",0,D10*IFERROR(INDEX(LISTS!$B$2:$B$8,MATCH(E10,LISTS!$A$2:$A$8,0)),1)) | G10: Income from all household members
A11: Earned Income | B11: Side jobs / odd jobs | E11: Monthly | F11: =IF(D11="",0,D11*IFERROR(INDEX(LISTS!$B$2:$B$8,MATCH(E11,LISTS!$A$2:$A$8,0)),1)) | G11: Income from all household members
A12: Earned Income | B12: Other (specify) | E12: Monthly | F12: =IF(D12="",0,D12*IFERROR(INDEX(LISTS!$B$2:$B$8,MATCH(E12,LISTS!$A$2:$A$8,0)),1)) | G12: Income from all household members
B13: BENEFITS | F13: =SUM(F14:F20)
A14: Benefits | B14: Social Security (retirement / survivor) | E14: Monthly | F14: =IF(D14="",0,D14*IFERROR(INDEX(LISTS!$B$2:$B$8,MATCH(E14,LISTS!$A$2:$A$8,0)),1)) | G14: Income from all household members
A15: Benefits | B15: SSI / SSDI | E15: Monthly | F15: =IF(D15="",0,D15*IFERROR(INDEX(LISTS!$B$2:$B$8,MATCH(E15,LISTS!$A$2:$A$8,0)),1)) | G15: Government assistance
A16: Benefits | B16: Pension / retirement withdrawals | E16: Monthly | F16: =IF(D16="",0,D16*IFERROR(INDEX(LISTS!$B$2:$B$8,MATCH(E16,LISTS!$A$2:$A$8,0)),1)) | G16: Income from all household members
A17: Benefits | B17: Unemployment | E17: Monthly | F17: =IF(D17="",0,D17*IFERROR(INDEX(LISTS!$B$2:$B$8,MATCH(E17,LISTS!$A$2:$A$8,0)),1)) | G17: Government assistance
A18: Benefits | B18: VA benefits | E18: Monthly | F18: =IF(D18="",0,D18*IFERROR(INDEX(LISTS!$B$2:$B$8,MATCH(E18,LISTS!$A$2:$A$8,0)),1)) | G18: Income from all household members
A19: Benefits | B19: Workers' comp / disability | E19: Monthly | F19: =IF(D19="",0,D19*IFERROR(INDEX(LISTS!$B$2:$B$8,MATCH(E19,LISTS!$A$2:$A$8,0)),1)) | G19: Income from all household members
A20: Benefits | B20: Other (specify) | E20: Monthly | F20: =IF(D20="",0,D20*IFERROR(INDEX(LISTS!$B$2:$B$8,MATCH(E20,LISTS!$A$2:$A$8,0)),1)) | G20: Income from all household members
B21: GOVERNMENT ASSISTANCE | F21: =SUM(F22:F28)
A22: Government Assistance | B22: SNAP (food stamps) | E22: Monthly | F22: =IF(D22="",0,D22*IFERROR(INDEX(LISTS!$B$2:$B$8,MATCH(E22,LISTS!$A$2:$A$8,0)),1)) | G22: Government assistance
A23: Government Assistance | B23: WIC | E23: Monthly | F23: =IF(D23="",0,D23*IFERROR(INDEX(LISTS!$B$2:$B$8,MATCH(E23,LISTS!$A$2:$A$8,0)),1)) | G23: Government assistance
A24: Government Assistance | B24: TANF / cash assistance | E24: Monthly | F24: =IF(D24="",0,D24*IFERROR(INDEX(LISTS!$B$2:$B$8,MATCH(E24,LISTS!$A$2:$A$8,0)),1)) | G24: Government assistance
A25: Government Assistance | B25: Housing assistance (Section 8, etc.) | E25: Monthly | F25: =IF(D25="",0,D25*IFERROR(INDEX(LISTS!$B$2:$B$8,MATCH(E25,LISTS!$A$2:$A$8,0)),1)) | G25: Government assistance
A26: Government Assistance | B26: Utility assistance (LIHEAP) | E26: Monthly | F26: =IF(D26="",0,D26*IFERROR(INDEX(LISTS!$B$2:$B$8,MATCH(E26,LISTS!$A$2:$A$8,0)),1)) | G26: Government assistance
A27: Government Assistance | B27: Medicaid / CHIP (value of premiums covered) | E27: Monthly | F27: =IF(D27="",0,D27*IFERROR(INDEX(LISTS!$B$2:$B$8,MATCH(E27,LISTS!$A$2:$A$8,0)),1)) | G27: Government assistance
A28: Government Assistance | B28: Other (specify) | E28: Monthly | F28: =IF(D28="",0,D28*IFERROR(INDEX(LISTS!$B$2:$B$8,MATCH(E28,LISTS!$A$2:$A$8,0)),1)) | G28: Government assistance
B29: SUPPORT RECEIVED | F29: =SUM(F30:F35)
A30: Support Received | B30: Child support received | E30: Monthly | F30: =IF(D30="",0,D30*IFERROR(INDEX(LISTS!$B$2:$B$8,MATCH(E30,LISTS!$A$2:$A$8,0)),1)) | G30: Other financial sources (family, others)
A31: Support Received | B31: Alimony received | E31: Monthly | F31: =IF(D31="",0,D31*IFERROR(INDEX(LISTS!$B$2:$B$8,MATCH(E31,LISTS!$A$2:$A$8,0)),1)) | G31: Other financial sources (family, others)
A32: Support Received | B32: Help from family | E32: Monthly | F32: =IF(D32="",0,D32*IFERROR(INDEX(LISTS!$B$2:$B$8,MATCH(E32,LISTS!$A$2:$A$8,0)),1)) | G32: Other financial sources (family, others)
A33: Support Received | B33: Help from friends / others | E33: Monthly | F33: =IF(D33="",0,D33*IFERROR(INDEX(LISTS!$B$2:$B$8,MATCH(E33,LISTS!$A$2:$A$8,0)),1)) | G33: Other financial sources (family, others)
A34: Support Received | B34: Current Church welfare assistance | E34: Monthly | F34: =IF(D34="",0,D34*IFERROR(INDEX(LISTS!$B$2:$B$8,MATCH(E34,LISTS!$A$2:$A$8,0)),1)) | G34: Other financial sources (family, others)
A35: Support Received | B35: Other (specify) | E35: Monthly | F35: =IF(D35="",0,D35*IFERROR(INDEX(LISTS!$B$2:$B$8,MATCH(E35,LISTS!$A$2:$A$8,0)),1)) | G35: Other financial sources (family, others)
B36: OTHER INCOME | F36: =SUM(F37:F40)
A37: Other Income | B37: Rental income (net) | E37: Monthly | F37: =IF(D37="",0,D37*IFERROR(INDEX(LISTS!$B$2:$B$8,MATCH(E37,LISTS!$A$2:$A$8,0)),1)) | G37: Income from all household members
A38: Other Income | B38: Tax refund (enter annual) | E38: Monthly | F38: =IF(D38="",0,D38*IFERROR(INDEX(LISTS!$B$2:$B$8,MATCH(E38,LISTS!$A$2:$A$8,0)),1)) | G38: Income from all household members
A39: Other Income | B39: Student aid / grants (living portion) | E39: Monthly | F39: =IF(D39="",0,D39*IFERROR(INDEX(LISTS!$B$2:$B$8,MATCH(E39,LISTS!$A$2:$A$8,0)),1)) | G39: Other financial sources (family, others)
A40: Other Income | B40: Other (specify) | E40: Monthly | F40: =IF(D40="",0,D40*IFERROR(INDEX(LISTS!$B$2:$B$8,MATCH(E40,LISTS!$A$2:$A$8,0)),1)) | G40: Other financial sources (family, others)
B42: TOTAL MONTHLY INCOME | F42: =SUMIFS(F5:F40,A5:A40,"<>")
...

Sheet EXPENSES
A1: Monthly Expenses
A2: Fill in the yellow cells only (blue text). Choose Frequency from the dropdown — the Monthly column converts automatically (e.g. Groceries $150 Weekly → $650.00/mo). Rename any 'Other' row to fit. Grey columns calculate on their own. Type drives the 'could be reduced' total on the Summary. 'Form line' maps each row to the official Self-Reliance Plan form.
A4: Category | B4: Expense | C4: Amount | D4: Frequency | E4: Monthly | F4: Type | G4: Auto Pay | H4: Due Date | I4: Past Due ($) | J4: SRP Form Line | K4: Notes | L4: Code
B5: TITHES & OFFERINGS | E5: =SUM(E6:E10) | I5: =SUM(I6:I10)
A6: Tithes & Offerings | B6: Tithing | D6: Monthly | E6: =IF(C6="",0,C6*IFERROR(INDEX(LISTS!$B$2:$B$8,MATCH(D6,LISTS!$A$2:$A$8,0)),1)) | F6: Essential | G6: FALSE | J6: Tithes, offerings | L6: TTH-01
A7: Tithes & Offerings | B7: Fast offering | D7: Monthly | E7: =IF(C7="",0,C7*IFERROR(INDEX(LISTS!$B$2:$B$8,MATCH(D7,LISTS!$A$2:$A$8,0)),1)) | F7: Essential | G7: FALSE | J7: Tithes, offerings | L7: TTH-02
A8: Tithes & Offerings | B8: Other donations (missionary, humanitarian, etc.) | D8: Monthly | E8: =IF(C8="",0,C8*IFERROR(INDEX(LISTS!$B$2:$B$8,MATCH(D8,LISTS!$A$2:$A$8,0)),1)) | F8: Important | G8: FALSE | J8: Tithes, offerings | L8: TTH-03
A9: Tithes & Offerings | B9: Other (specify) | D9: Monthly | E9: =IF(C9="",0,C9*IFERROR(INDEX(LISTS!$B$2:$B$8,MATCH(D9,LISTS!$A$2:$A$8,0)),1)) | F9: Important | G9: FALSE | J9: Other | L9: TTH-04
A10: Tithes & Offerings | B10: Other (specify) | D10: Monthly | E10: =IF(C10="",0,C10*IFERROR(INDEX(LISTS!$B$2:$B$8,MATCH(D10,LISTS!$A$2:$A$8,0)),1)) | F10: Important | G10: FALSE | J10: Other | L10: TTH-05
B11: HOUSING | E11: =SUM(E12:E19) | I11: =SUM(I12:I19)
A12: Housing | B12: Rent or mortgage | D12: Monthly | E12: =IF(C12="",0,C12*IFERROR(INDEX(LISTS!$B$2:$B$8,MATCH(D12,LISTS!$A$2:$A$8,0)),1)) | F12: Essential | G12: FALSE | J12: Housing | L12: HOU-01
A13: Housing | B13: Property taxes (if not in mortgage) | D13: Monthly | E13: =IF(C13="",0,C13*IFERROR(INDEX(LISTS!$B$2:$B$8,MATCH(D13,LISTS!$A$2:$A$8,0)),1)) | F13: Essential | G13: FALSE | J13: Housing | L13: HOU-02
A14: Housing | B14: Homeowners / renters insurance | D14: Monthly | E14: =IF(C14="",0,C14*IFERROR(INDEX(LISTS!$B$2:$B$8,MATCH(D14,LISTS!$A$2:$A$8,0)),1)) | F14: Essential | G14: FALSE | J14: Housing | L14: HOU-03
A15: Housing | B15: HOA or lot rent | D15: Monthly | E15: =IF(C15="",0,C15*IFERROR(INDEX(LISTS!$B$2:$B$8,MATCH(D15,LISTS!$A$2:$A$8,0)),1)) | F15: Essential | G15: FALSE | J15: Housing | L15: HOU-04
A16: Housing | B16: Home repairs & maintenance | D16: Monthly | E16: =IF(C16="",0,C16*IFERROR(INDEX(LISTS!$B$2:$B$8,MATCH(D16,LISTS!$A$2:$A$8,0)),1)) | F16: Important | G16: FALSE | J16: Housing | L16: HOU-05
A17: Housing | B17: Storage unit | D17: Monthly | E17: =IF(C17="",0,C17*IFERROR(INDEX(LISTS!$B$2:$B$8,MATCH(D17,LISTS!$A$2:$A$8,0)),1)) | F17: Discretionary | G17: FALSE | J17: Housing | L17: HOU-06
A18: Housing | B18: Other (specify) | D18: Monthly | E18: =IF(C18="",0,C18*IFERROR(INDEX(LISTS!$B$2:$B$8,MATCH(D18,LISTS!$A$2:$A$8,0)),1)) | F18: Important | G18: FALSE | J18: Other | L18: HOU-07
A19: Housing | B19: Other (specify) | D19: Monthly | E19: =IF(C19="",0,C19*IFERROR(INDEX(LISTS!$B$2:$B$8,MATCH(D19,LISTS!$A$2:$A$8,0)),1)) | F19: Important | G19: FALSE | J19: Other | L19: HOU-08
B20: UTILITIES | E20: =SUM(E21:E29) | I20: =SUM(I21:I29)
A21: Utilities | B21: Electricity | D21: Monthly | E21: =IF(C21="",0,C21*IFERROR(INDEX(LISTS!$B$2:$B$8,MATCH(D21,LISTS!$A$2:$A$8,0)),1)) | F21: Essential | G21: FALSE | J21: Electricity, fuel | L21: UTL-01
A22: Utilities | B22: Natural gas / propane / heating oil / wood | D22: Monthly | E22: =IF(C22="",0,C22*IFERROR(INDEX(LISTS!$B$2:$B$8,MATCH(D22,LISTS!$A$2:$A$8,0)),1)) | F22: Essential | G22: FALSE | J22: Electricity, fuel | L22: UTL-02
A23: Utilities | B23: Water & sewer | D23: Monthly | E23: =IF(C23="",0,C23*IFERROR(INDEX(LISTS!$B$2:$B$8,MATCH(D23,LISTS!$A$2:$A$8,0)),1)) | F23: Essential | G23: FALSE | J23: Water | L23: UTL-03
A24: Utilities | B24: Trash | D24: Monthly | E24: =IF(C24="",0,C24*IFERROR(INDEX(LISTS!$B$2:$B$8,MATCH(D24,LISTS!$A$2:$A$8,0)),1)) | F24: Essential | G24: FALSE | J24: Other | L24: UTL-04
A25: Utilities | B25: Phone (cell & landline) | D25: Monthly | E25: =IF(C25="",0,C25*IFERROR(INDEX(LISTS!$B$2:$B$8,MATCH(D25,LISTS!$A$2:$A$8,0)),1)) | F25: Important | G25: FALSE | J25: Other | L25: UTL-05
A26: Utilities | B26: Internet | D26: Monthly | E26: =IF(C26="",0,C26*IFERROR(INDEX(LISTS!$B$2:$B$8,MATCH(D26,LISTS!$A$2:$A$8,0)),1)) | F26: Essential | G26: FALSE | J26: Other | L26: UTL-06
A27: Utilities | B27: Cable / satellite TV | D27: Monthly | E27: =IF(C27="",0,C27*IFERROR(INDEX(LISTS!$B$2:$B$8,MATCH(D27,LISTS!$A$2:$A$8,0)),1)) | F27: Discretionary | G27: FALSE | J27: Other | L27: UTL-07
A28: Utilities | B28: Other (specify) | D28: Monthly | E28: =IF(C28="",0,C28*IFERROR(INDEX(LISTS!$B$2:$B$8,MATCH(D28,LISTS!$A$2:$A$8,0)),1)) | F28: Important | G28: FALSE | J28: Other | L28: UTL-08
A29: Utilities | B29: Other (specify) | D29: Monthly | E29: =IF(C29="",0,C29*IFERROR(INDEX(LISTS!$B$2:$B$8,MATCH(D29,LISTS!$A$2:$A$8,0)),1)) | F29: Important | G29: FALSE | J29: Other | L29: UTL-09
B30: FOOD | E30: =SUM(E31:E36) | I30: =SUM(I31:I36)
A31: Food | B31: Groceries | D31: Monthly | E31: =IF(C31="",0,C31*IFERROR(INDEX(LISTS!$B$2:$B$8,MATCH(D31,LISTS!$A$2:$A$8,0)),1)) | F31: Essential | G31: FALSE | J31: Food | L31: FOD-01
A32: Food | B32: Eating out & fast food | D32: Monthly | E32: =IF(C32="",0,C32*IFERROR(INDEX(LISTS!$B$2:$B$8,MATCH(D32,LISTS!$A$2:$A$8,0)),1)) | F32: Discretionary | G32: FALSE | J32: Food | L32: FOD-02
A33: Food | B33: School lunches | D33: Monthly | E33: =IF(C33="",0,C33*IFERROR(INDEX(LISTS!$B$2:$B$8,MATCH(D33,LISTS!$A$2:$A$8,0)),1)) | F33: Important | G33: FALSE | J33: Food | L33: FOD-03
A34: Food | B34: Baby formula & food | D34: Monthly | E34: =IF(C34="",0,C34*IFERROR(INDEX(LISTS!$B$2:$B$8,MATCH(D34,LISTS!$A$2:$A$8,0)),1)) | F34: Essential | G34: FALSE | J34: Food | L34: FOD-04
A35: Food | B35: Other (specify) | D35: Monthly | E35: =IF(C35="",0,C35*IFERROR(INDEX(LISTS!$B$2:$B$8,MATCH(D35,LISTS!$A$2:$A$8,0)),1)) | F35: Important | G35: FALSE | J35: Other | L35: FOD-05
A36: Food | B36: Other (specify) | D36: Monthly | E36: =IF(C36="",0,C36*IFERROR(INDEX(LISTS!$B$2:$B$8,MATCH(D36,LISTS!$A$2:$A$8,0)),1)) | F36: Important | G36: FALSE | J36: Other | L36: FOD-06
B37: HOUSEHOLD & PERSONAL | E37: =SUM(E38:E44) | I37: =SUM(I38:I44)
A38: Household & Personal | B38: Toiletries & hygiene | D38: Monthly | E38: =IF(C38="",0,C38*IFERROR(INDEX(LISTS!$B$2:$B$8,MATCH(D38,LISTS!$A$2:$A$8,0)),1)) | F38: Essential | G38: FALSE | J38: Other | L38: HHP-01
A39: Household & Personal | B39: Cleaning supplies & paper goods | D39: Monthly | E39: =IF(C39="",0,C39*IFERROR(INDEX(LISTS!$B$2:$B$8,MATCH(D39,LISTS!$A$2:$A$8,0)),1)) | F39: Essential | G39: FALSE | J39: Other | L39: HHP-02
A40: Household & Personal | B40: Laundry / laundromat | D40: Monthly | E40: =IF(C40="",0,C40*IFERROR(INDEX(LISTS!$B$2:$B$8,MATCH(D40,LISTS!$A$2:$A$8,0)),1)) | F40: Essential | G40: FALSE | J40: Other | L40: HHP-03
A41: Household & Personal | B41: Haircuts & grooming | D41: Monthly | E41: =IF(C41="",0,C41*IFERROR(INDEX(LISTS!$B$2:$B$8,MATCH(D41,LISTS!$A$2:$A$8,0)),1)) | F41: Discretionary | G41: FALSE | J41: Other | L41: HHP-04
...

Sheet DEBTS
A1: Debts & Past-Due Accounts
A2: List each debt NOT already counted as rent/mortgage or car payment on the Expenses tab (credit cards, medical bills, personal / payday / title loans, buy-now-pay-later, back taxes, collections, student loans). Monthly payments flow to the Debt Payments line on Expenses.
A4: Creditor | B4: Debt Type | C4: Balance Owed | D4: Interest Rate | E4: Min. Monthly Payment | F4: Months Behind | G4: Past Due ($) | H4: Auto Pay | I4: Due Date | J4: Notes
H5: FALSE
H6: FALSE
H7: FALSE
H8: FALSE
H9: FALSE
H10: FALSE
H11: FALSE
H12: FALSE
H13: FALSE
H14: FALSE
H15: FALSE
H16: FALSE
... H20: FALSE
A21: TOTALS | C21: =SUM(C5:C20) | E21: =SUM(E5:E20) | G21: =SUM(G5:G20)
A22: Enter interest rate as a percent (e.g. 24.99%).

Sheet SUPPORT PLAN
A1: Monthly Support Plan (3 months)
A2: Planned support for each expense line for the next 3 months. Enter amounts in the yellow cells under the source covering it (Member, Family, Church, Social Services, Other). Each month has its own Need column (defaults: Month-1 = Total Due incl. past due, Months 2–3 = Monthly Need — overwrite as needed). Each month's Total turns green when that month's need is covered and orange when it isn't; 3-Month Need and Covered − Need use these month needs. Plan start month (C4) dates the plan for the Expenditure Summary.
A4: Plan start month: | E4: Member: | F4: =IF(PLAN!B5="","",PLAN!B5)
G5: ="Month-1"&IF($C$4="",""," "&UPPER(TEXT(EDATE($C$4,0),"mmm-yyyy"))) | N5: ="Month-2"&IF($C$4="",""," "&UPPER(TEXT(EDATE($C$4,1),"mmm-yyyy"))) | U5: ="Month-3"&IF($C$4="",""," "&UPPER(TEXT(EDATE($C$4,2),"mmm-yyyy"))) | AB5: 3-MONTH TOTALS BY SOURCE
A6: Code | B6: Expense | C6: Monthly Need (Expenses) | D6: Past Due (Expenses) | E6: Total Due (Need + Past Due) | F6: Paid To / Vendor | G6: Member's Month-1 Need | H6: Member Efforts | I6: Family Contribution | J6: Church Assistance | K6: Social Services | L6: Other Support | M6: Month-1 Total | N6: Member's Month-2 Need | O6: Member Efforts | P6: Family Contribution | Q6: Church Assistance | R6: Social Services | S6: Other Support | T6: Month-2 Total | U6: Member's Month-3 Need | V6: Member Efforts | W6: Family Contribution | X6: Church Assistance | Y6: Social Services | Z6: Other Support | AA6: Month-3 Total | AB6: Member | AC6: Family | AD6: Church | AE6: Social Services | AF6: Other | AG6: 3-Month Total Covered | AH6: 3-Month Need (Month-1 + 2 + 3 Need) | AI6: Covered − Need | AJ6: Notes / Conditions
B7: TITHES & OFFERINGS | C7: =SUM(C8:C12) | D7: =SUM(D8:D12) | E7: =SUM(E8:E12) | G7: =SUM(G8:G12) | H7: =SUM(H8:H12) | I7: =SUM(I8:I12) | J7: =SUM(J8:J12) | K7: =SUM(K8:K12) | L7: =SUM(L8:L12) | M7: =SUM(M8:M12) | N7: =SUM(N8:N12) | ... AI7: =SUM(AI8:AI12)
A8: =EXPENSES!L6 | B8: =EXPENSES!B6 | C8: =EXPENSES!E6 | D8: =EXPENSES!I6 | E8: =C8+D8 | M8: =SUM(H8:L8) | T8: =SUM(O8:S8) | AA8: =SUM(V8:Z8) | AB8: =H8+O8+V8 | AC8: =I8+P8+W8 | AD8: =J8+Q8+X8 | AE8: =K8+R8+Y8 | AF8: =L8+S8+Z8 | AG8: =M8+T8+AA8 | AH8: =G8+N8+U8 | AI8: =AG8-AH8
A9: =EXPENSES!L7 | B9: =EXPENSES!B7 | C9: =EXPENSES!E7 | D9: =EXPENSES!I7 | E9: =C9+D9 | M9: =SUM(H9:L9) | T9: =SUM(O9:S9) | AA9: =SUM(V9:Z9) | AB9: =H9+O9+V9 | AC9: =I9+P9+W9 | AD9: =J9+Q9+X9 | AE9: =K9+R9+Y9 | AF9: =L9+S9+Z9 | AG9: =M9+T9+AA9 | AH9: =G9+N9+U9 | AI9: =AG9-AH9
A10: =EXPENSES!L8 | B10: =EXPENSES!B8 | C10: =EXPENSES!E8 | D10: =EXPENSES!I8 | E10: =C10+D10 | M10: =SUM(H10:L10) | T10: =SUM(O10:S10) | AA10: =SUM(V10:Z10) | AB10: =H10+O10+V10 | AC10: =I10+P10+W10 | AD10: =J10+Q10+X10 | AE10: =K10+R10+Y10 | AF10: =L10+S10+Z10 | AG10: =M10+T10+AA10 | AH10: =G10+N10+U10 | AI10: =AG10-AH10
A11: =EXPENSES!L9 | B11: =EXPENSES!B9 | C11: =EXPENSES!E9 | D11: =EXPENSES!I9 | E11: =C11+D11 | M11: =SUM(H11:L11) | T11: =SUM(O11:S11) | AA11: =SUM(V11:Z11) | AB11: =H11+O11+V11 | AC11: =I11+P11+W11 | AD11: =J11+Q11+X11 | AE11: =K11+R11+Y11 | AF11: =L11+S11+Z11 | AG11: =M11+T11+AA11 | AH11: =G11+N11+U11 | AI11: =AG11-AH11
A12: =EXPENSES!L10 | B12: =EXPENSES!B10 | C12: =EXPENSES!E10 | D12: =EXPENSES!I10 | E12: =C12+D12 | M12: =SUM(H12:L12) | T12: =SUM(O12:S12) | AA12: =SUM(V12:Z12) | AB12: =H12+O12+V12 | AC12: =I12+P12+W12 | AD12: =J12+Q12+X12 | AE12: =K12+R12+Y12 | AF12: =L12+S12+Z12 | AG12: =M12+T12+AA12 | AH12: =G12+N12+U12 | AI12: =AG12-AH12
B13: HOUSING | C13: =SUM(C14:C21) | D13: =SUM(D14:D21) | E13: =SUM(E14:E21) | G13: =SUM(G14:G21) | H13: =SUM(H14:H21) | I13: =SUM(I14:I21) | J13: =SUM(J14:J21) | K13: =SUM(K14:K21) | L13: =SUM(L14:L21) | M13: =SUM(M14:M21) | N13: =SUM(N14:N21) | ... AI13: =SUM(AI14:AI21)
A14: =EXPENSES!L12 | B14: =EXPENSES!B12 | C14: =EXPENSES!E12 | D14: =EXPENSES!I12 | E14: =C14+D14 | M14: =SUM(H14:L14) | T14: =SUM(O14:S14) | AA14: =SUM(V14:Z14) | AB14: =H14+O14+V14 | AC14: =I14+P14+W14 | AD14: =J14+Q14+X14 | AE14: =K14+R14+Y14 | AF14: =L14+S14+Z14 | AG14: =M14+T14+AA14 | AH14: =G14+N14+U14 | AI14: =AG14-AH14
A15: =EXPENSES!L13 | B15: =EXPENSES!B13 | C15: =EXPENSES!E13 | D15: =EXPENSES!I13 | E15: =C15+D15 | M15: =SUM(H15:L15) | T15: =SUM(O15:S15) | AA15: =SUM(V15:Z15) | AB15: =H15+O15+V15 | AC15: =I15+P15+W15 | AD15: =J15+Q15+X15 | AE15: =K15+R15+Y15 | AF15: =L15+S15+Z15 | AG15: =M15+T15+AA15 | AH15: =G15+N15+U15 | AI15: =AG15-AH15
A16: =EXPENSES!L14 | B16: =EXPENSES!B14 | C16: =EXPENSES!E14 | D16: =EXPENSES!I14 | E16: =C16+D16 | M16: =SUM(H16:L16) | T16: =SUM(O16:S16) | AA16: =SUM(V16:Z16) | AB16: =H16+O16+V16 | AC16: =I16+P16+W16 | AD16: =J16+Q16+X16 | AE16: =K16+R16+Y16 | AF16: =L16+S16+Z16 | AG16: =M16+T16+AA16 | AH16: =G16+N16+U16 | AI16: =AG16-AH16
A17: =EXPENSES!L15 | B17: =EXPENSES!B15 | C17: =EXPENSES!E15 | D17: =EXPENSES!I15 | E17: =C17+D17 | M17: =SUM(H17:L17) | T17: =SUM(O17:S17) | AA17: =SUM(V17:Z17) | AB17: =H17+O17+V17 | AC17: =I17+P17+W17 | AD17: =J17+Q17+X17 | AE17: =K17+R17+Y17 | AF17: =L17+S17+Z17 | AG17: =M17+T17+AA17 | AH17: =G17+N17+U17 | AI17: =AG17-AH17
A18: =EXPENSES!L16 | B18: =EXPENSES!B16 | C18: =EXPENSES!E16 | D18: =EXPENSES!I16 | E18: =C18+D18 | M18: =SUM(H18:L18) | T18: =SUM(O18:S18) | AA18: =SUM(V18:Z18) | AB18: =H18+O18+V18 | AC18: =I18+P18+W18 | AD18: =J18+Q18+X18 | AE18: =K18+R18+Y18 | AF18: =L18+S18+Z18 | AG18: =M18+T18+AA18 | AH18: =G18+N18+U18 | AI18: =AG18-AH18
A19: =EXPENSES!L17 | B19: =EXPENSES!B17 | C19: =EXPENSES!E17 | D19: =EXPENSES!I17 | E19: =C19+D19 | M19: =SUM(H19:L19) | T19: =SUM(O19:S19) | AA19: =SUM(V19:Z19) | AB19: =H19+O19+V19 | AC19: =I19+P19+W19 | AD19: =J19+Q19+X19 | AE19: =K19+R19+Y19 | AF19: =L19+S19+Z19 | AG19: =M19+T19+AA19 | AH19: =G19+N19+U19 | AI19: =AG19-AH19
A20: =EXPENSES!L18 | B20: =EXPENSES!B18 | C20: =EXPENSES!E18 | D20: =EXPENSES!I18 | E20: =C20+D20 | M20: =SUM(H20:L20) | T20: =SUM(O20:S20) | AA20: =SUM(V20:Z20) | AB20: =H20+O20+V20 | AC20: =I20+P20+W20 | AD20: =J20+Q20+X20 | AE20: =K20+R20+Y20 | AF20: =L20+S20+Z20 | AG20: =M20+T20+AA20 | AH20: =G20+N20+U20 | AI20: =AG20-AH20
A21: =EXPENSES!L19 | B21: =EXPENSES!B19 | C21: =EXPENSES!E19 | D21: =EXPENSES!I19 | E21: =C21+D21 | M21: =SUM(H21:L21) | T21: =SUM(O21:S21) | AA21: =SUM(V21:Z21) | AB21: =H21+O21+V21 | AC21: =I21+P21+W21 | AD21: =J21+Q21+X21 | AE21: =K21+R21+Y21 | AF21: =L21+S21+Z21 | AG21: =M21+T21+AA21 | AH21: =G21+N21+U21 | AI21: =AG21-AH21
B22: UTILITIES | C22: =SUM(C23:C31) | D22: =SUM(D23:D31) | E22: =SUM(E23:E31) | G22: =SUM(G23:G31) | H22: =SUM(H23:H31) | I22: =SUM(I23:I31) | J22: =SUM(J23:J31) | K22: =SUM(K23:K31) | L22: =SUM(L23:L31) | M22: =SUM(M23:M31) | N22: =SUM(N23:N31) | ... AI22: =SUM(AI23:AI31)
A23: =EXPENSES!L21 | B23: =EXPENSES!B21 | C23: =EXPENSES!E21 | D23: =EXPENSES!I21 | E23: =C23+D23 | M23: =SUM(H23:L23) | T23: =SUM(O23:S23) | AA23: =SUM(V23:Z23) | AB23: =H23+O23+V23 | AC23: =I23+P23+W23 | AD23: =J23+Q23+X23 | AE23: =K23+R23+Y23 | AF23: =L23+S23+Z23 | AG23: =M23+T23+AA23 | AH23: =G23+N23+U23 | AI23: =AG23-AH23
A24: =EXPENSES!L22 | B24: =EXPENSES!B22 | C24: =EXPENSES!E22 | D24: =EXPENSES!I22 | E24: =C24+D24 | M24: =SUM(H24:L24) | T24: =SUM(O24:S24) | AA24: =SUM(V24:Z24) | AB24: =H24+O24+V24 | AC24: =I24+P24+W24 | AD24: =J24+Q24+X24 | AE24: =K24+R24+Y24 | AF24: =L24+S24+Z24 | AG24: =M24+T24+AA24 | AH24: =G24+N24+U24 | AI24: =AG24-AH24
A25: =EXPENSES!L23 | B25: =EXPENSES!B23 | C25: =EXPENSES!E23 | D25: =EXPENSES!I23 | E25: =C25+D25 | M25: =SUM(H25:L25) | T25: =SUM(O25:S25) | AA25: =SUM(V25:Z25) | AB25: =H25+O25+V25 | AC25: =I25+P25+W25 | AD25: =J25+Q25+X25 | AE25: =K25+R25+Y25 | AF25: =L25+S25+Z25 | AG25: =M25+T25+AA25 | AH25: =G25+N25+U25 | AI25: =AG25-AH25
A26: =EXPENSES!L24 | B26: =EXPENSES!B24 | C26: =EXPENSES!E24 | D26: =EXPENSES!I24 | E26: =C26+D26 | M26: =SUM(H26:L26) | T26: =SUM(O26:S26) | AA26: =SUM(V26:Z26) | AB26: =H26+O26+V26 | AC26: =I26+P26+W26 | AD26: =J26+Q26+X26 | AE26: =K26+R26+Y26 | AF26: =L26+S26+Z26 | AG26: =M26+T26+AA26 | AH26: =G26+N26+U26 | AI26: =AG26-AH26
A27: =EXPENSES!L25 | B27: =EXPENSES!B25 | C27: =EXPENSES!E25 | D27: =EXPENSES!I25 | E27: =C27+D27 | M27: =SUM(H27:L27) | T27: =SUM(O27:S27) | AA27: =SUM(V27:Z27) | AB27: =H27+O27+V27 | AC27: =I27+P27+W27 | AD27: =J27+Q27+X27 | AE27: =K27+R27+Y27 | AF27: =L27+S27+Z27 | AG27: =M27+T27+AA27 | AH27: =G27+N27+U27 | AI27: =AG27-AH27
A28: =EXPENSES!L26 | B28: =EXPENSES!B26 | C28: =EXPENSES!E26 | D28: =EXPENSES!I26 | E28: =C28+D28 | M28: =SUM(H28:L28) | T28: =SUM(O28:S28) | AA28: =SUM(V28:Z28) | AB28: =H28+O28+V28 | AC28: =I28+P28+W28 | AD28: =J28+Q28+X28 | AE28: =K28+R28+Y28 | AF28: =L28+S28+Z28 | AG28: =M28+T28+AA28 | AH28: =G28+N28+U28 | AI28: =AG28-AH28
A29: =EXPENSES!L27 | B29: =EXPENSES!B27 | C29: =EXPENSES!E27 | D29: =EXPENSES!I27 | E29: =C29+D29 | M29: =SUM(H29:L29) | T29: =SUM(O29:S29) | AA29: =SUM(V29:Z29) | AB29: =H29+O29+V29 | AC29: =I29+P29+W29 | AD29: =J29+Q29+X29 | AE29: =K29+R29+Y29 | AF29: =L29+S29+Z29 | AG29: =M29+T29+AA29 | AH29: =G29+N29+U29 | AI29: =AG29-AH29
A30: =EXPENSES!L28 | B30: =EXPENSES!B28 | C30: =EXPENSES!E28 | D30: =EXPENSES!I28 | E30: =C30+D30 | M30: =SUM(H30:L30) | T30: =SUM(O30:S30) | AA30: =SUM(V30:Z30) | AB30: =H30+O30+V30 | AC30: =I30+P30+W30 | AD30: =J30+Q30+X30 | AE30: =K30+R30+Y30 | AF30: =L30+S30+Z30 | AG30: =M30+T30+AA30 | AH30: =G30+N30+U30 | AI30: =AG30-AH30
A31: =EXPENSES!L29 | B31: =EXPENSES!B29 | C31: =EXPENSES!E29 | D31: =EXPENSES!I29 | E31: =C31+D31 | M31: =SUM(H31:L31) | T31: =SUM(O31:S31) | AA31: =SUM(V31:Z31) | AB31: =H31+O31+V31 | AC31: =I31+P31+W31 | AD31: =J31+Q31+X31 | AE31: =K31+R31+Y31 | AF31: =L31+S31+Z31 | AG31: =M31+T31+AA31 | AH31: =G31+N31+U31 | AI31: =AG31-AH31
B32: FOOD | C32: =SUM(C33:C38) | D32: =SUM(D33:D38) | E32: =SUM(E33:E38) | G32: =SUM(G33:G38) | H32: =SUM(H33:H38) | I32: =SUM(I33:I38) | J32: =SUM(J33:J38) | K32: =SUM(K33:K38) | L32: =SUM(L33:L38) | M32: =SUM(M33:M38) | N32: =SUM(N33:N38) | ... AI32: =SUM(AI33:AI38)
A33: =EXPENSES!L31 | B33: =EXPENSES!B31 | C33: =EXPENSES!E31 | D33: =EXPENSES!I31 | E33: =C33+D33 | M33: =SUM(H33:L33) | T33: =SUM(O33:S33) | AA33: =SUM(V33:Z33) | AB33: =H33+O33+V33 | AC33: =I33+P33+W33 | AD33: =J33+Q33+X33 | AE33: =K33+R33+Y33 | AF33: =L33+S33+Z33 | AG33: =M33+T33+AA33 | AH33: =G33+N33+U33 | AI33: =AG33-AH33
A34: =EXPENSES!L32 | B34: =EXPENSES!B32 | C34: =EXPENSES!E32 | D34: =EXPENSES!I32 | E34: =C34+D34 | M34: =SUM(H34:L34) | T34: =SUM(O34:S34) | AA34: =SUM(V34:Z34) | AB34: =H34+O34+V34 | AC34: =I34+P34+W34 | AD34: =J34+Q34+X34 | AE34: =K34+R34+Y34 | AF34: =L34+S34+Z34 | AG34: =M34+T34+AA34 | AH34: =G34+N34+U34 | AI34: =AG34-AH34
A35: =EXPENSES!L33 | B35: =EXPENSES!B33 | C35: =EXPENSES!E33 | D35: =EXPENSES!I33 | E35: =C35+D35 | M35: =SUM(H35:L35) | T35: =SUM(O35:S35) | AA35: =SUM(V35:Z35) | AB35: =H35+O35+V35 | AC35: =I35+P35+W35 | AD35: =J35+Q35+X35 | AE35: =K35+R35+Y35 | AF35: =L35+S35+Z35 | AG35: =M35+T35+AA35 | AH35: =G35+N35+U35 | AI35: =AG35-AH35
A36: =EXPENSES!L34 | B36: =EXPENSES!B34 | C36: =EXPENSES!E34 | D36: =EXPENSES!I34 | E36: =C36+D36 | M36: =SUM(H36:L36) | T36: =SUM(O36:S36) | AA36: =SUM(V36:Z36) | AB36: =H36+O36+V36 | AC36: =I36+P36+W36 | AD36: =J36+Q36+X36 | AE36: =K36+R36+Y36 | AF36: =L36+S36+Z36 | AG36: =M36+T36+AA36 | AH36: =G36+N36+U36 | AI36: =AG36-AH36
A37: =EXPENSES!L35 | B37: =EXPENSES!B35 | C37: =EXPENSES!E35 | D37: =EXPENSES!I35 | E37: =C37+D37 | M37: =SUM(H37:L37) | T37: =SUM(O37:S37) | AA37: =SUM(V37:Z37) | AB37: =H37+O37+V37 | AC37: =I37+P37+W37 | AD37: =J37+Q37+X37 | AE37: =K37+R37+Y37 | AF37: =L37+S37+Z37 | AG37: =M37+T37+AA37 | AH37: =G37+N37+U37 | AI37: =AG37-AH37
A38: =EXPENSES!L36 | B38: =EXPENSES!B36 | C38: =EXPENSES!E36 | D38: =EXPENSES!I36 | E38: =C38+D38 | M38: =SUM(H38:L38) | T38: =SUM(O38:S38) | AA38: =SUM(V38:Z38) | AB38: =H38+O38+V38 | AC38: =I38+P38+W38 | AD38: =J38+Q38+X38 | AE38: =K38+R38+Y38 | AF38: =L38+S38+Z38 | AG38: =M38+T38+AA38 | AH38: =G38+N38+U38 | AI38: =AG38-AH38
B39: HOUSEHOLD & PERSONAL | C39: =SUM(C40:C46) | D39: =SUM(D40:D46) | E39: =SUM(E40:E46) | G39: =SUM(G40:G46) | H39: =SUM(H40:H46) | I39: =SUM(I40:I46) | J39: =SUM(J40:J46) | K39: =SUM(K40:K46) | L39: =SUM(L40:L46) | M39: =SUM(M40:M46) | N39: =SUM(N40:N46) | ... AI39: =SUM(AI40:AI46)
A40: =EXPENSES!L38 | B40: =EXPENSES!B38 | C40: =EXPENSES!E38 | D40: =EXPENSES!I38 | E40: =C40+D40 | M40: =SUM(H40:L40) | T40: =SUM(O40:S40) | AA40: =SUM(V40:Z40) | AB40: =H40+O40+V40 | AC40: =I40+P40+W40 | AD40: =J40+Q40+X40 | AE40: =K40+R40+Y40 | AF40: =L40+S40+Z40 | AG40: =M40+T40+AA40 | AH40: =G40+N40+U40 | AI40: =AG40-AH40
A41: =EXPENSES!L39 | B41: =EXPENSES!B39 | C41: =EXPENSES!E39 | D41: =EXPENSES!I39 | E41: =C41+D41 | M41: =SUM(H41:L41) | T41: =SUM(O41:S41) | AA41: =SUM(V41:Z41) | AB41: =H41+O41+V41 | AC41: =I41+P41+W41 | AD41: =J41+Q41+X41 | AE41: =K41+R41+Y41 | AF41: =L41+S41+Z41 | AG41: =M41+T41+AA41 | AH41: =G41+N41+U41 | AI41: =AG41-AH41
...

Sheet EXPENDITURE LOG
A1: Expenditure Log
A2: Record every purchase or payment, one per row (yellow cells). Pick the Expense Line from the dropdown — it matches the Expenses tab — and Code and Category fill in automatically. Example: 11/04/2026 | Weekly groceries | Walmart | $142.67 | FOD-01 - Groceries | Member | Debit card. A row with an amount but no Expense Line turns orange.
A4: Date | B4: Description | C4: Payee / Vendor | D4: Amount | E4: Expense Line | F4: Paid By | G4: Payment Method | H4: Receipt? | I4: Notes | J4: Code | K4: Category | M4: Total recorded: | N4: =SUM(D5:D504)
J5: =IF(E5="","",LEFT(E5,6)) | K5: =IF(J5="","",IFERROR(INDEX(EXPENSES!$A$5:$A$126,MATCH(J5,EXPENSES!$L$5:$L$126,0)),"")) | M5: Entries: | N5: =COUNT(D5:D504)
J6: =IF(E6="","",LEFT(E6,6)) | K6: =IF(J6="","",IFERROR(INDEX(EXPENSES!$A$5:$A$126,MATCH(J6,EXPENSES!$L$5:$L$126,0)),"")) | M6: Uncoded entries: | N6: =COUNTIFS(D5:D504,"<>",E5:E504,"")
J7: =IF(E7="","",LEFT(E7,6)) | K7: =IF(J7="","",IFERROR(INDEX(EXPENSES!$A$5:$A$126,MATCH(J7,EXPENSES!$L$5:$L$126,0)),""))
J8: =IF(E8="","",LEFT(E8,6)) | K8: =IF(J8="","",IFERROR(INDEX(EXPENSES!$A$5:$A$126,MATCH(J8,EXPENSES!$L$5:$L$126,0)),""))
J9: =IF(E9="","",LEFT(E9,6)) | K9: =IF(J9="","",IFERROR(INDEX(EXPENSES!$A$5:$A$126,MATCH(J9,EXPENSES!$L$5:$L$126,0)),""))
J10: =IF(E10="","",LEFT(E10,6)) | K10: =IF(J10="","",IFERROR(INDEX(EXPENSES!$A$5:$A$126,MATCH(J10,EXPENSES!$L$5:$L$126,0)),""))
J11: =IF(E11="","",LEFT(E11,6)) | K11: =IF(J11="","",IFERROR(INDEX(EXPENSES!$A$5:$A$126,MATCH(J11,EXPENSES!$L$5:$L$126,0)),""))
J12: =IF(E12="","",LEFT(E12,6)) | K12: =IF(J12="","",IFERROR(INDEX(EXPENSES!$A$5:$A$126,MATCH(J12,EXPENSES!$L$5:$L$126,0)),""))
J13: =IF(E13="","",LEFT(E13,6)) | K13: =IF(J13="","",IFERROR(INDEX(EXPENSES!$A$5:$A$126,MATCH(J13,EXPENSES!$L$5:$L$126,0)),""))
J14: =IF(E14="","",LEFT(E14,6)) | K14: =IF(J14="","",IFERROR(INDEX(EXPENSES!$A$5:$A$126,MATCH(J14,EXPENSES!$L$5:$L$126,0)),""))
J15: =IF(E15="","",LEFT(E15,6)) | K15: =IF(J15="","",IFERROR(INDEX(EXPENSES!$A$5:$A$126,MATCH(J15,EXPENSES!$L$5:$L$126,0)),""))
J16: =IF(E16="","",LEFT(E16,6)) | K16: =IF(J16="","",IFERROR(INDEX(EXPENSES!$A$5:$A$126,MATCH(J16,EXPENSES!$L$5:$L$126,0)),""))
J17: =IF(E17="","",LEFT(E17,6)) | K17: =IF(J17="","",IFERROR(INDEX(EXPENSES!$A$5:$A$126,MATCH(J17,EXPENSES!$L$5:$L$126,0)),""))
J18: =IF(E18="","",LEFT(E18,6)) | K18: =IF(J18="","",IFERROR(INDEX(EXPENSES!$A$5:$A$126,MATCH(J18,EXPENSES!$L$5:$L$126,0)),""))
... J504: =IF(E504="","",LEFT(E504,6)) | K504: =IF(J504="","",IFERROR(INDEX(EXPENSES!$A$5:$A$126,MATCH(J504,EXPENSES!$L$5:$L$126,0)),""))
C505: TOTAL | D505: =SUM(D5:D504)

Sheet EXPENDITURE SUMMARY
A1: Expenditure Summary
A2: Totals from the Expenditure Log for each expense line. Pick a month in C4 to see that month's spending against the budget and the support plan, and cumulative spending from the plan start month through the selected month. Nothing else to enter on this tab.
A4: Select month: | E4: Month # of plan: | F4: =(YEAR($C$4)-YEAR('SUPPORT PLAN'!$C$4))*12+MONTH($C$4)-MONTH('SUPPORT PLAN'!$C$4)+1 | G4: Plan start: | H4: ='SUPPORT PLAN'!$C$4
A6: Code | B6: Expense | C6: Monthly Budget | D6: Planned Support — All Sources (Selected Month) | E6: Spent in Selected Month | F6: Church-Paid in Selected Month | G6: Over / (Under) Budget — Month | H6: Cumulative Spent (Plan Start → Selected Month) | I6: Cumulative Budget (Plan Start → Selected Month) | J6: Cumulative Over / (Under) | K6: Total Recorded (All Dates)
B7: TITHES & OFFERINGS | C7: =SUM(C8:C12) | D7: =SUM(D8:D12) | E7: =SUM(E8:E12) | F7: =SUM(F8:F12) | G7: =SUM(G8:G12) | H7: =SUM(H8:H12) | I7: =SUM(I8:I12) | J7: =SUM(J8:J12) | K7: =SUM(K8:K12)
A8: =EXPENSES!L6 | B8: =EXPENSES!B6 | C8: =EXPENSES!E6 | D8: =IF(AND($F$4>=1,$F$4<=3),CHOOSE($F$4,'SUPPORT PLAN'!$M8,'SUPPORT PLAN'!$T8,'SUPPORT PLAN'!$AA8),0) | E8: =SUMIFS('EXPENDITURE LOG'!$D$5:$D$504,'EXPENDITURE LOG'!$J$5:$J$504,$A8,'EXPENDITURE LOG'!$A$5:$A$504,">="&$C$4,'EXPENDITURE LOG'!$A$5:$A$504,"<"&EDATE($C$4,1)) | F8: =SUMIFS('EXPENDITURE LOG'!$D$5:$D$504,'EXPENDITURE LOG'!$J$5:$J$504,$A8,'EXPENDITURE LOG'!$A$5:$A$504,">="&$C$4,'EXPENDITURE LOG'!$A$5:$A$504,"<"&EDATE($C$4,1),'EXPENDITURE LOG'!$F$5:$F$504,"Church*") | G8: =E8-C8 | H8: =SUMIFS('EXPENDITURE LOG'!$D$5:$D$504,'EXPENDITURE LOG'!$J$5:$J$504,$A8,'EXPENDITURE LOG'!$A$5:$A$504,">="&'SUPPORT PLAN'!$C$4,'EXPENDITURE LOG'!$A$5:$A$504,"<"&EDATE($C$4,1)) | I8: =C8*MAX(0,$F$4) | J8: =H8-I8 | K8: =SUMIFS('EXPENDITURE LOG'!$D$5:$D$504,'EXPENDITURE LOG'!$J$5:$J$504,$A8)
A9: =EXPENSES!L7 | B9: =EXPENSES!B7 | C9: =EXPENSES!E7 | D9: =IF(AND($F$4>=1,$F$4<=3),CHOOSE($F$4,'SUPPORT PLAN'!$M9,'SUPPORT PLAN'!$T9,'SUPPORT PLAN'!$AA9),0) | E9: =SUMIFS('EXPENDITURE LOG'!$D$5:$D$504,'EXPENDITURE LOG'!$J$5:$J$504,$A9,'EXPENDITURE LOG'!$A$5:$A$504,">="&$C$4,'EXPENDITURE LOG'!$A$5:$A$504,"<"&EDATE($C$4,1)) | F9: =SUMIFS('EXPENDITURE LOG'!$D$5:$D$504,'EXPENDITURE LOG'!$J$5:$J$504,$A9,'EXPENDITURE LOG'!$A$5:$A$504,">="&$C$4,'EXPENDITURE LOG'!$A$5:$A$504,"<"&EDATE($C$4,1),'EXPENDITURE LOG'!$F$5:$F$504,"Church*") | G9: =E9-C9 | H9: =SUMIFS('EXPENDITURE LOG'!$D$5:$D$504,'EXPENDITURE LOG'!$J$5:$J$504,$A9,'EXPENDITURE LOG'!$A$5:$A$504,">="&'SUPPORT PLAN'!$C$4,'EXPENDITURE LOG'!$A$5:$A$504,"<"&EDATE($C$4,1)) | I9: =C9*MAX(0,$F$4) | J9: =H9-I9 | K9: =SUMIFS('EXPENDITURE LOG'!$D$5:$D$504,'EXPENDITURE LOG'!$J$5:$J$504,$A9)
A10: =EXPENSES!L8 | B10: =EXPENSES!B8 | C10: =EXPENSES!E8 | D10: =IF(AND($F$4>=1,$F$4<=3),CHOOSE($F$4,'SUPPORT PLAN'!$M10,'SUPPORT PLAN'!$T10,'SUPPORT PLAN'!$AA10),0) | E10: =SUMIFS('EXPENDITURE LOG'!$D$5:$D$504,'EXPENDITURE LOG'!$J$5:$J$504,$A10,'EXPENDITURE LOG'!$A$5:$A$504,">="&$C$4,'EXPENDITURE LOG'!$A$5:$A$504,"<"&EDATE($C$4,1)) | F10: =SUMIFS('EXPENDITURE LOG'!$D$5:$D$504,'EXPENDITURE LOG'!$J$5:$J$504,$A10,'EXPENDITURE LOG'!$A$5:$A$504,">="&$C$4,'EXPENDITURE LOG'!$A$5:$A$504,"<"&EDATE($C$4,1),'EXPENDITURE LOG'!$F$5:$F$504,"Church*") | G10: =E10-C10 | H10: =SUMIFS('EXPENDITURE LOG'!$D$5:$D$504,'EXPENDITURE LOG'!$J$5:$J$504,$A10,'EXPENDITURE LOG'!$A$5:$A$504,">="&'SUPPORT PLAN'!$C$4,'EXPENDITURE LOG'!$A$5:$A$504,"<"&EDATE($C$4,1)) | I10: =C10*MAX(0,$F$4) | J10: =H10-I10 | K10: =SUMIFS('EXPENDITURE LOG'!$D$5:$D$504,'EXPENDITURE LOG'!$J$5:$J$504,$A10)
A11: =EXPENSES!L9 | B11: =EXPENSES!B9 | C11: =EXPENSES!E9 | D11: =IF(AND($F$4>=1,$F$4<=3),CHOOSE($F$4,'SUPPORT PLAN'!$M11,'SUPPORT PLAN'!$T11,'SUPPORT PLAN'!$AA11),0) | E11: =SUMIFS('EXPENDITURE LOG'!$D$5:$D$504,'EXPENDITURE LOG'!$J$5:$J$504,$A11,'EXPENDITURE LOG'!$A$5:$A$504,">="&$C$4,'EXPENDITURE LOG'!$A$5:$A$504,"<"&EDATE($C$4,1)) | F11: =SUMIFS('EXPENDITURE LOG'!$D$5:$D$504,'EXPENDITURE LOG'!$J$5:$J$504,$A11,'EXPENDITURE LOG'!$A$5:$A$504,">="&$C$4,'EXPENDITURE LOG'!$A$5:$A$504,"<"&EDATE($C$4,1),'EXPENDITURE LOG'!$F$5:$F$504,"Church*") | G11: =E11-C11 | H11: =SUMIFS('EXPENDITURE LOG'!$D$5:$D$504,'EXPENDITURE LOG'!$J$5:$J$504,$A11,'EXPENDITURE LOG'!$A$5:$A$504,">="&'SUPPORT PLAN'!$C$4,'EXPENDITURE LOG'!$A$5:$A$504,"<"&EDATE($C$4,1)) | I11: =C11*MAX(0,$F$4) | J11: =H11-I11 | K11: =SUMIFS('EXPENDITURE LOG'!$D$5:$D$504,'EXPENDITURE LOG'!$J$5:$J$504,$A11)
A12: =EXPENSES!L10 | B12: =EXPENSES!B10 | C12: =EXPENSES!E10 | D12: =IF(AND($F$4>=1,$F$4<=3),CHOOSE($F$4,'SUPPORT PLAN'!$M12,'SUPPORT PLAN'!$T12,'SUPPORT PLAN'!$AA12),0) | E12: =SUMIFS('EXPENDITURE LOG'!$D$5:$D$504,'EXPENDITURE LOG'!$J$5:$J$504,$A12,'EXPENDITURE LOG'!$A$5:$A$504,">="&$C$4,'EXPENDITURE LOG'!$A$5:$A$504,"<"&EDATE($C$4,1)) | F12: =SUMIFS('EXPENDITURE LOG'!$D$5:$D$504,'EXPENDITURE LOG'!$J$5:$J$504,$A12,'EXPENDITURE LOG'!$A$5:$A$504,">="&$C$4,'EXPENDITURE LOG'!$A$5:$A$504,"<"&EDATE($C$4,1),'EXPENDITURE LOG'!$F$5:$F$504,"Church*") | G12: =E12-C12 | H12: =SUMIFS('EXPENDITURE LOG'!$D$5:$D$504,'EXPENDITURE LOG'!$J$5:$J$504,$A12,'EXPENDITURE LOG'!$A$5:$A$504,">="&'SUPPORT PLAN'!$C$4,'EXPENDITURE LOG'!$A$5:$A$504,"<"&EDATE($C$4,1)) | I12: =C12*MAX(0,$F$4) | J12: =H12-I12 | K12: =SUMIFS('EXPENDITURE LOG'!$D$5:$D$504,'EXPENDITURE LOG'!$J$5:$J$504,$A12)
B13: HOUSING | C13: =SUM(C14:C21) | D13: =SUM(D14:D21) | E13: =SUM(E14:E21) | F13: =SUM(F14:F21) | G13: =SUM(G14:G21) | H13: =SUM(H14:H21) | I13: =SUM(I14:I21) | J13: =SUM(J14:J21) | K13: =SUM(K14:K21)
A14: =EXPENSES!L12 | B14: =EXPENSES!B12 | C14: =EXPENSES!E12 | D14: =IF(AND($F$4>=1,$F$4<=3),CHOOSE($F$4,'SUPPORT PLAN'!$M14,'SUPPORT PLAN'!$T14,'SUPPORT PLAN'!$AA14),0) | E14: =SUMIFS('EXPENDITURE LOG'!$D$5:$D$504,'EXPENDITURE LOG'!$J$5:$J$504,$A14,'EXPENDITURE LOG'!$A$5:$A$504,">="&$C$4,'EXPENDITURE LOG'!$A$5:$A$504,"<"&EDATE($C$4,1)) | F14: =SUMIFS('EXPENDITURE LOG'!$D$5:$D$504,'EXPENDITURE LOG'!$J$5:$J$504,$A14,'EXPENDITURE LOG'!$A$5:$A$504,">="&$C$4,'EXPENDITURE LOG'!$A$5:$A$504,"<"&EDATE($C$4,1),'EXPENDITURE LOG'!$F$5:$F$504,"Church*") | G14: =E14-C14 | H14: =SUMIFS('EXPENDITURE LOG'!$D$5:$D$504,'EXPENDITURE LOG'!$J$5:$J$504,$A14,'EXPENDITURE LOG'!$A$5:$A$504,">="&'SUPPORT PLAN'!$C$4,'EXPENDITURE LOG'!$A$5:$A$504,"<"&EDATE($C$4,1)) | I14: =C14*MAX(0,$F$4) | J14: =H14-I14 | K14: =SUMIFS('EXPENDITURE LOG'!$D$5:$D$504,'EXPENDITURE LOG'!$J$5:$J$504,$A14)
A15: =EXPENSES!L13 | B15: =EXPENSES!B13 | C15: =EXPENSES!E13 | D15: =IF(AND($F$4>=1,$F$4<=3),CHOOSE($F$4,'SUPPORT PLAN'!$M15,'SUPPORT PLAN'!$T15,'SUPPORT PLAN'!$AA15),0) | E15: =SUMIFS('EXPENDITURE LOG'!$D$5:$D$504,'EXPENDITURE LOG'!$J$5:$J$504,$A15,'EXPENDITURE LOG'!$A$5:$A$504,">="&$C$4,'EXPENDITURE LOG'!$A$5:$A$504,"<"&EDATE($C$4,1)) | F15: =SUMIFS('EXPENDITURE LOG'!$D$5:$D$504,'EXPENDITURE LOG'!$J$5:$J$504,$A15,'EXPENDITURE LOG'!$A$5:$A$504,">="&$C$4,'EXPENDITURE LOG'!$A$5:$A$504,"<"&EDATE($C$4,1),'EXPENDITURE LOG'!$F$5:$F$504,"Church*") | G15: =E15-C15 | H15: =SUMIFS('EXPENDITURE LOG'!$D$5:$D$504,'EXPENDITURE LOG'!$J$5:$J$504,$A15,'EXPENDITURE LOG'!$A$5:$A$504,">="&'SUPPORT PLAN'!$C$4,'EXPENDITURE LOG'!$A$5:$A$504,"<"&EDATE($C$4,1)) | I15: =C15*MAX(0,$F$4) | J15: =H15-I15 | K15: =SUMIFS('EXPENDITURE LOG'!$D$5:$D$504,'EXPENDITURE LOG'!$J$5:$J$504,$A15)
A16: =EXPENSES!L14 | B16: =EXPENSES!B14 | C16: =EXPENSES!E14 | D16: =IF(AND($F$4>=1,$F$4<=3),CHOOSE($F$4,'SUPPORT PLAN'!$M16,'SUPPORT PLAN'!$T16,'SUPPORT PLAN'!$AA16),0) | E16: =SUMIFS('EXPENDITURE LOG'!$D$5:$D$504,'EXPENDITURE LOG'!$J$5:$J$504,$A16,'EXPENDITURE LOG'!$A$5:$A$504,">="&$C$4,'EXPENDITURE LOG'!$A$5:$A$504,"<"&EDATE($C$4,1)) | F16: =SUMIFS('EXPENDITURE LOG'!$D$5:$D$504,'EXPENDITURE LOG'!$J$5:$J$504,$A16,'EXPENDITURE LOG'!$A$5:$A$504,">="&$C$4,'EXPENDITURE LOG'!$A$5:$A$504,"<"&EDATE($C$4,1),'EXPENDITURE LOG'!$F$5:$F$504,"Church*") | G16: =E16-C16 | H16: =SUMIFS('EXPENDITURE LOG'!$D$5:$D$504,'EXPENDITURE LOG'!$J$5:$J$504,$A16,'EXPENDITURE LOG'!$A$5:$A$504,">="&'SUPPORT PLAN'!$C$4,'EXPENDITURE LOG'!$A$5:$A$504,"<"&EDATE($C$4,1)) | I16: =C16*MAX(0,$F$4) | J16: =H16-I16 | K16: =SUMIFS('EXPENDITURE LOG'!$D$5:$D$504,'EXPENDITURE LOG'!$J$5:$J$504,$A16)
A17: =EXPENSES!L15 | B17: =EXPENSES!B15 | C17: =EXPENSES!E15 | D17: =IF(AND($F$4>=1,$F$4<=3),CHOOSE($F$4,'SUPPORT PLAN'!$M17,'SUPPORT PLAN'!$T17,'SUPPORT PLAN'!$AA17),0) | E17: =SUMIFS('EXPENDITURE LOG'!$D$5:$D$504,'EXPENDITURE LOG'!$J$5:$J$504,$A17,'EXPENDITURE LOG'!$A$5:$A$504,">="&$C$4,'EXPENDITURE LOG'!$A$5:$A$504,"<"&EDATE($C$4,1)) | F17: =SUMIFS('EXPENDITURE LOG'!$D$5:$D$504,'EXPENDITURE LOG'!$J$5:$J$504,$A17,'EXPENDITURE LOG'!$A$5:$A$504,">="&$C$4,'EXPENDITURE LOG'!$A$5:$A$504,"<"&EDATE($C$4,1),'EXPENDITURE LOG'!$F$5:$F$504,"Church*") | G17: =E17-C17 | H17: =SUMIFS('EXPENDITURE LOG'!$D$5:$D$504,'EXPENDITURE LOG'!$J$5:$J$504,$A17,'EXPENDITURE LOG'!$A$5:$A$504,">="&'SUPPORT PLAN'!$C$4,'EXPENDITURE LOG'!$A$5:$A$504,"<"&EDATE($C$4,1)) | I17: =C17*MAX(0,$F$4) | J17: =H17-I17 | K17: =SUMIFS('EXPENDITURE LOG'!$D$5:$D$504,'EXPENDITURE LOG'!$J$5:$J$504,$A17)
A18: =EXPENSES!L16 | B18: =EXPENSES!B16 | C18: =EXPENSES!E16 | D18: =IF(AND($F$4>=1,$F$4<=3),CHOOSE($F$4,'SUPPORT PLAN'!$M18,'SUPPORT PLAN'!$T18,'SUPPORT PLAN'!$AA18),0) | E18: =SUMIFS('EXPENDITURE LOG'!$D$5:$D$504,'EXPENDITURE LOG'!$J$5:$J$504,$A18,'EXPENDITURE LOG'!$A$5:$A$504,">="&$C$4,'EXPENDITURE LOG'!$A$5:$A$504,"<"&EDATE($C$4,1)) | F18: =SUMIFS('EXPENDITURE LOG'!$D$5:$D$504,'EXPENDITURE LOG'!$J$5:$J$504,$A18,'EXPENDITURE LOG'!$A$5:$A$504,">="&$C$4,'EXPENDITURE LOG'!$A$5:$A$504,"<"&EDATE($C$4,1),'EXPENDITURE LOG'!$F$5:$F$504,"Church*") | G18: =E18-C18 | H18: =SUMIFS('EXPENDITURE LOG'!$D$5:$D$504,'EXPENDITURE LOG'!$J$5:$J$504,$A18,'EXPENDITURE LOG'!$A$5:$A$504,">="&'SUPPORT PLAN'!$C$4,'EXPENDITURE LOG'!$A$5:$A$504,"<"&EDATE($C$4,1)) | I18: =C18*MAX(0,$F$4) | J18: =H18-I18 | K18: =SUMIFS('EXPENDITURE LOG'!$D$5:$D$504,'EXPENDITURE LOG'!$J$5:$J$504,$A18)
A19: =EXPENSES!L17 | B19: =EXPENSES!B17 | C19: =EXPENSES!E17 | D19: =IF(AND($F$4>=1,$F$4<=3),CHOOSE($F$4,'SUPPORT PLAN'!$M19,'SUPPORT PLAN'!$T19,'SUPPORT PLAN'!$AA19),0) | E19: =SUMIFS('EXPENDITURE LOG'!$D$5:$D$504,'EXPENDITURE LOG'!$J$5:$J$504,$A19,'EXPENDITURE LOG'!$A$5:$A$504,">="&$C$4,'EXPENDITURE LOG'!$A$5:$A$504,"<"&EDATE($C$4,1)) | F19: =SUMIFS('EXPENDITURE LOG'!$D$5:$D$504,'EXPENDITURE LOG'!$J$5:$J$504,$A19,'EXPENDITURE LOG'!$A$5:$A$504,">="&$C$4,'EXPENDITURE LOG'!$A$5:$A$504,"<"&EDATE($C$4,1),'EXPENDITURE LOG'!$F$5:$F$504,"Church*") | G19: =E19-C19 | H19: =SUMIFS('EXPENDITURE LOG'!$D$5:$D$504,'EXPENDITURE LOG'!$J$5:$J$504,$A19,'EXPENDITURE LOG'!$A$5:$A$504,">="&'SUPPORT PLAN'!$C$4,'EXPENDITURE LOG'!$A$5:$A$504,"<"&EDATE($C$4,1)) | I19: =C19*MAX(0,$F$4) | J19: =H19-I19 | K19: =SUMIFS('EXPENDITURE LOG'!$D$5:$D$504,'EXPENDITURE LOG'!$J$5:$J$504,$A19)
A20: =EXPENSES!L18 | B20: =EXPENSES!B18 | C20: =EXPENSES!E18 | D20: =IF(AND($F$4>=1,$F$4<=3),CHOOSE($F$4,'SUPPORT PLAN'!$M20,'SUPPORT PLAN'!$T20,'SUPPORT PLAN'!$AA20),0) | E20: =SUMIFS('EXPENDITURE LOG'!$D$5:$D$504,'EXPENDITURE LOG'!$J$5:$J$504,$A20,'EXPENDITURE LOG'!$A$5:$A$504,">="&$C$4,'EXPENDITURE LOG'!$A$5:$A$504,"<"&EDATE($C$4,1)) | F20: =SUMIFS('EXPENDITURE LOG'!$D$5:$D$504,'EXPENDITURE LOG'!$J$5:$J$504,$A20,'EXPENDITURE LOG'!$A$5:$A$504,">="&$C$4,'EXPENDITURE LOG'!$A$5:$A$504,"<"&EDATE($C$4,1),'EXPENDITURE LOG'!$F$5:$F$504,"Church*") | G20: =E20-C20 | H20: =SUMIFS('EXPENDITURE LOG'!$D$5:$D$504,'EXPENDITURE LOG'!$J$5:$J$504,$A20,'EXPENDITURE LOG'!$A$5:$A$504,">="&'SUPPORT PLAN'!$C$4,'EXPENDITURE LOG'!$A$5:$A$504,"<"&EDATE($C$4,1)) | I20: =C20*MAX(0,$F$4) | J20: =H20-I20 | K20: =SUMIFS('EXPENDITURE LOG'!$D$5:$D$504,'EXPENDITURE LOG'!$J$5:$J$504,$A20)
A21: =EXPENSES!L19 | B21: =EXPENSES!B19 | C21: =EXPENSES!E19 | D21: =IF(AND($F$4>=1,$F$4<=3),CHOOSE($F$4,'SUPPORT PLAN'!$M21,'SUPPORT PLAN'!$T21,'SUPPORT PLAN'!$AA21),0) | E21: =SUMIFS('EXPENDITURE LOG'!$D$5:$D$504,'EXPENDITURE LOG'!$J$5:$J$504,$A21,'EXPENDITURE LOG'!$A$5:$A$504,">="&$C$4,'EXPENDITURE LOG'!$A$5:$A$504,"<"&EDATE($C$4,1)) | F21: =SUMIFS('EXPENDITURE LOG'!$D$5:$D$504,'EXPENDITURE LOG'!$J$5:$J$504,$A21,'EXPENDITURE LOG'!$A$5:$A$504,">="&$C$4,'EXPENDITURE LOG'!$A$5:$A$504,"<"&EDATE($C$4,1),'EXPENDITURE LOG'!$F$5:$F$504,"Church*") | G21: =E21-C21 | H21: =SUMIFS('EXPENDITURE LOG'!$D$5:$D$504,'EXPENDITURE LOG'!$J$5:$J$504,$A21,'EXPENDITURE LOG'!$A$5:$A$504,">="&'SUPPORT PLAN'!$C$4,'EXPENDITURE LOG'!$A$5:$A$504,"<"&EDATE($C$4,1)) | I21: =C21*MAX(0,$F$4) | J21: =H21-I21 | K21: =SUMIFS('EXPENDITURE LOG'!$D$5:$D$504,'EXPENDITURE LOG'!$J$5:$J$504,$A21)
B22: UTILITIES | C22: =SUM(C23:C31) | D22: =SUM(D23:D31) | E22: =SUM(E23:E31) | F22: =SUM(F23:F31) | G22: =SUM(G23:G31) | H22: =SUM(H23:H31) | I22: =SUM(I23:I31) | J22: =SUM(J23:J31) | K22: =SUM(K23:K31)
A23: =EXPENSES!L21 | B23: =EXPENSES!B21 | C23: =EXPENSES!E21 | D23: =IF(AND($F$4>=1,$F$4<=3),CHOOSE($F$4,'SUPPORT PLAN'!$M23,'SUPPORT PLAN'!$T23,'SUPPORT PLAN'!$AA23),0) | E23: =SUMIFS('EXPENDITURE LOG'!$D$5:$D$504,'EXPENDITURE LOG'!$J$5:$J$504,$A23,'EXPENDITURE LOG'!$A$5:$A$504,">="&$C$4,'EXPENDITURE LOG'!$A$5:$A$504,"<"&EDATE($C$4,1)) | F23: =SUMIFS('EXPENDITURE LOG'!$D$5:$D$504,'EXPENDITURE LOG'!$J$5:$J$504,$A23,'EXPENDITURE LOG'!$A$5:$A$504,">="&$C$4,'EXPENDITURE LOG'!$A$5:$A$504,"<"&EDATE($C$4,1),'EXPENDITURE LOG'!$F$5:$F$504,"Church*") | G23: =E23-C23 | H23: =SUMIFS('EXPENDITURE LOG'!$D$5:$D$504,'EXPENDITURE LOG'!$J$5:$J$504,$A23,'EXPENDITURE LOG'!$A$5:$A$504,">="&'SUPPORT PLAN'!$C$4,'EXPENDITURE LOG'!$A$5:$A$504,"<"&EDATE($C$4,1)) | I23: =C23*MAX(0,$F$4) | J23: =H23-I23 | K23: =SUMIFS('EXPENDITURE LOG'!$D$5:$D$504,'EXPENDITURE LOG'!$J$5:$J$504,$A23)
A24: =EXPENSES!L22 | B24: =EXPENSES!B22 | C24: =EXPENSES!E22 | D24: =IF(AND($F$4>=1,$F$4<=3),CHOOSE($F$4,'SUPPORT PLAN'!$M24,'SUPPORT PLAN'!$T24,'SUPPORT PLAN'!$AA24),0) | E24: =SUMIFS('EXPENDITURE LOG'!$D$5:$D$504,'EXPENDITURE LOG'!$J$5:$J$504,$A24,'EXPENDITURE LOG'!$A$5:$A$504,">="&$C$4,'EXPENDITURE LOG'!$A$5:$A$504,"<"&EDATE($C$4,1)) | F24: =SUMIFS('EXPENDITURE LOG'!$D$5:$D$504,'EXPENDITURE LOG'!$J$5:$J$504,$A24,'EXPENDITURE LOG'!$A$5:$A$504,">="&$C$4,'EXPENDITURE LOG'!$A$5:$A$504,"<"&EDATE($C$4,1),'EXPENDITURE LOG'!$F$5:$F$504,"Church*") | G24: =E24-C24 | H24: =SUMIFS('EXPENDITURE LOG'!$D$5:$D$504,'EXPENDITURE LOG'!$J$5:$J$504,$A24,'EXPENDITURE LOG'!$A$5:$A$504,">="&'SUPPORT PLAN'!$C$4,'EXPENDITURE LOG'!$A$5:$A$504,"<"&EDATE($C$4,1)) | I24: =C24*MAX(0,$F$4) | J24: =H24-I24 | K24: =SUMIFS('EXPENDITURE LOG'!$D$5:$D$504,'EXPENDITURE LOG'!$J$5:$J$504,$A24)
A25: =EXPENSES!L23 | B25: =EXPENSES!B23 | C25: =EXPENSES!E23 | D25: =IF(AND($F$4>=1,$F$4<=3),CHOOSE($F$4,'SUPPORT PLAN'!$M25,'SUPPORT PLAN'!$T25,'SUPPORT PLAN'!$AA25),0) | E25: =SUMIFS('EXPENDITURE LOG'!$D$5:$D$504,'EXPENDITURE LOG'!$J$5:$J$504,$A25,'EXPENDITURE LOG'!$A$5:$A$504,">="&$C$4,'EXPENDITURE LOG'!$A$5:$A$504,"<"&EDATE($C$4,1)) | F25: =SUMIFS('EXPENDITURE LOG'!$D$5:$D$504,'EXPENDITURE LOG'!$J$5:$J$504,$A25,'EXPENDITURE LOG'!$A$5:$A$504,">="&$C$4,'EXPENDITURE LOG'!$A$5:$A$504,"<"&EDATE($C$4,1),'EXPENDITURE LOG'!$F$5:$F$504,"Church*") | G25: =E25-C25 | H25: =SUMIFS('EXPENDITURE LOG'!$D$5:$D$504,'EXPENDITURE LOG'!$J$5:$J$504,$A25,'EXPENDITURE LOG'!$A$5:$A$504,">="&'SUPPORT PLAN'!$C$4,'EXPENDITURE LOG'!$A$5:$A$504,"<"&EDATE($C$4,1)) | I25: =C25*MAX(0,$F$4) | J25: =H25-I25 | K25: =SUMIFS('EXPENDITURE LOG'!$D$5:$D$504,'EXPENDITURE LOG'!$J$5:$J$504,$A25)
A26: =EXPENSES!L24 | B26: =EXPENSES!B24 | C26: =EXPENSES!E24 | D26: =IF(AND($F$4>=1,$F$4<=3),CHOOSE($F$4,'SUPPORT PLAN'!$M26,'SUPPORT PLAN'!$T26,'SUPPORT PLAN'!$AA26),0) | E26: =SUMIFS('EXPENDITURE LOG'!$D$5:$D$504,'EXPENDITURE LOG'!$J$5:$J$504,$A26,'EXPENDITURE LOG'!$A$5:$A$504,">="&$C$4,'EXPENDITURE LOG'!$A$5:$A$504,"<"&EDATE($C$4,1)) | F26: =SUMIFS('EXPENDITURE LOG'!$D$5:$D$504,'EXPENDITURE LOG'!$J$5:$J$504,$A26,'EXPENDITURE LOG'!$A$5:$A$504,">="&$C$4,'EXPENDITURE LOG'!$A$5:$A$504,"<"&EDATE($C$4,1),'EXPENDITURE LOG'!$F$5:$F$504,"Church*") | G26: =E26-C26 | H26: =SUMIFS('EXPENDITURE LOG'!$D$5:$D$504,'EXPENDITURE LOG'!$J$5:$J$504,$A26,'EXPENDITURE LOG'!$A$5:$A$504,">="&'SUPPORT PLAN'!$C$4,'EXPENDITURE LOG'!$A$5:$A$504,"<"&EDATE($C$4,1)) | I26: =C26*MAX(0,$F$4) | J26: =H26-I26 | K26: =SUMIFS('EXPENDITURE LOG'!$D$5:$D$504,'EXPENDITURE LOG'!$J$5:$J$504,$A26)
A27: =EXPENSES!L25 | B27: =EXPENSES!B25 | C27: =EXPENSES!E25 | D27: =IF(AND($F$4>=1,$F$4<=3),CHOOSE($F$4,'SUPPORT PLAN'!$M27,'SUPPORT PLAN'!$T27,'SUPPORT PLAN'!$AA27),0) | E27: =SUMIFS('EXPENDITURE LOG'!$D$5:$D$504,'EXPENDITURE LOG'!$J$5:$J$504,$A27,'EXPENDITURE LOG'!$A$5:$A$504,">="&$C$4,'EXPENDITURE LOG'!$A$5:$A$504,"<"&EDATE($C$4,1)) | F27: =SUMIFS('EXPENDITURE LOG'!$D$5:$D$504,'EXPENDITURE LOG'!$J$5:$J$504,$A27,'EXPENDITURE LOG'!$A$5:$A$504,">="&$C$4,'EXPENDITURE LOG'!$A$5:$A$504,"<"&EDATE($C$4,1),'EXPENDITURE LOG'!$F$5:$F$504,"Church*") | G27: =E27-C27 | H27: =SUMIFS('EXPENDITURE LOG'!$D$5:$D$504,'EXPENDITURE LOG'!$J$5:$J$504,$A27,'EXPENDITURE LOG'!$A$5:$A$504,">="&'SUPPORT PLAN'!$C$4,'EXPENDITURE LOG'!$A$5:$A$504,"<"&EDATE($C$4,1)) | I27: =C27*MAX(0,$F$4) | J27: =H27-I27 | K27: =SUMIFS('EXPENDITURE LOG'!$D$5:$D$504,'EXPENDITURE LOG'!$J$5:$J$504,$A27)
A28: =EXPENSES!L26 | B28: =EXPENSES!B26 | C28: =EXPENSES!E26 | D28: =IF(AND($F$4>=1,$F$4<=3),CHOOSE($F$4,'SUPPORT PLAN'!$M28,'SUPPORT PLAN'!$T28,'SUPPORT PLAN'!$AA28),0) | E28: =SUMIFS('EXPENDITURE LOG'!$D$5:$D$504,'EXPENDITURE LOG'!$J$5:$J$504,$A28,'EXPENDITURE LOG'!$A$5:$A$504,">="&$C$4,'EXPENDITURE LOG'!$A$5:$A$504,"<"&EDATE($C$4,1)) | F28: =SUMIFS('EXPENDITURE LOG'!$D$5:$D$504,'EXPENDITURE LOG'!$J$5:$J$504,$A28,'EXPENDITURE LOG'!$A$5:$A$504,">="&$C$4,'EXPENDITURE LOG'!$A$5:$A$504,"<"&EDATE($C$4,1),'EXPENDITURE LOG'!$F$5:$F$504,"Church*") | G28: =E28-C28 | H28: =SUMIFS('EXPENDITURE LOG'!$D$5:$D$504,'EXPENDITURE LOG'!$J$5:$J$504,$A28,'EXPENDITURE LOG'!$A$5:$A$504,">="&'SUPPORT PLAN'!$C$4,'EXPENDITURE LOG'!$A$5:$A$504,"<"&EDATE($C$4,1)) | I28: =C28*MAX(0,$F$4) | J28: =H28-I28 | K28: =SUMIFS('EXPENDITURE LOG'!$D$5:$D$504,'EXPENDITURE LOG'!$J$5:$J$504,$A28)
A29: =EXPENSES!L27 | B29: =EXPENSES!B27 | C29: =EXPENSES!E27 | D29: =IF(AND($F$4>=1,$F$4<=3),CHOOSE($F$4,'SUPPORT PLAN'!$M29,'SUPPORT PLAN'!$T29,'SUPPORT PLAN'!$AA29),0) | E29: =SUMIFS('EXPENDITURE LOG'!$D$5:$D$504,'EXPENDITURE LOG'!$J$5:$J$504,$A29,'EXPENDITURE LOG'!$A$5:$A$504,">="&$C$4,'EXPENDITURE LOG'!$A$5:$A$504,"<"&EDATE($C$4,1)) | F29: =SUMIFS('EXPENDITURE LOG'!$D$5:$D$504,'EXPENDITURE LOG'!$J$5:$J$504,$A29,'EXPENDITURE LOG'!$A$5:$A$504,">="&$C$4,'EXPENDITURE LOG'!$A$5:$A$504,"<"&EDATE($C$4,1),'EXPENDITURE LOG'!$F$5:$F$504,"Church*") | G29: =E29-C29 | H29: =SUMIFS('EXPENDITURE LOG'!$D$5:$D$504,'EXPENDITURE LOG'!$J$5:$J$504,$A29,'EXPENDITURE LOG'!$A$5:$A$504,">="&'SUPPORT PLAN'!$C$4,'EXPENDITURE LOG'!$A$5:$A$504,"<"&EDATE($C$4,1)) | I29: =C29*MAX(0,$F$4) | J29: =H29-I29 | K29: =SUMIFS('EXPENDITURE LOG'!$D$5:$D$504,'EXPENDITURE LOG'!$J$5:$J$504,$A29)
A30: =EXPENSES!L28 | B30: =EXPENSES!B28 | C30: =EXPENSES!E28 | D30: =IF(AND($F$4>=1,$F$4<=3),CHOOSE($F$4,'SUPPORT PLAN'!$M30,'SUPPORT PLAN'!$T30,'SUPPORT PLAN'!$AA30),0) | E30: =SUMIFS('EXPENDITURE LOG'!$D$5:$D$504,'EXPENDITURE LOG'!$J$5:$J$504,$A30,'EXPENDITURE LOG'!$A$5:$A$504,">="&$C$4,'EXPENDITURE LOG'!$A$5:$A$504,"<"&EDATE($C$4,1)) | F30: =SUMIFS('EXPENDITURE LOG'!$D$5:$D$504,'EXPENDITURE LOG'!$J$5:$J$504,$A30,'EXPENDITURE LOG'!$A$5:$A$504,">="&$C$4,'EXPENDITURE LOG'!$A$5:$A$504,"<"&EDATE($C$4,1),'EXPENDITURE LOG'!$F$5:$F$504,"Church*") | G30: =E30-C30 | H30: =SUMIFS('EXPENDITURE LOG'!$D$5:$D$504,'EXPENDITURE LOG'!$J$5:$J$504,$A30,'EXPENDITURE LOG'!$A$5:$A$504,">="&'SUPPORT PLAN'!$C$4,'EXPENDITURE LOG'!$A$5:$A$504,"<"&EDATE($C$4,1)) | I30: =C30*MAX(0,$F$4) | J30: =H30-I30 | K30: =SUMIFS('EXPENDITURE LOG'!$D$5:$D$504,'EXPENDITURE LOG'!$J$5:$J$504,$A30)
A31: =EXPENSES!L29 | B31: =EXPENSES!B29 | C31: =EXPENSES!E29 | D31: =IF(AND($F$4>=1,$F$4<=3),CHOOSE($F$4,'SUPPORT PLAN'!$M31,'SUPPORT PLAN'!$T31,'SUPPORT PLAN'!$AA31),0) | E31: =SUMIFS('EXPENDITURE LOG'!$D$5:$D$504,'EXPENDITURE LOG'!$J$5:$J$504,$A31,'EXPENDITURE LOG'!$A$5:$A$504,">="&$C$4,'EXPENDITURE LOG'!$A$5:$A$504,"<"&EDATE($C$4,1)) | F31: =SUMIFS('EXPENDITURE LOG'!$D$5:$D$504,'EXPENDITURE LOG'!$J$5:$J$504,$A31,'EXPENDITURE LOG'!$A$5:$A$504,">="&$C$4,'EXPENDITURE LOG'!$A$5:$A$504,"<"&EDATE($C$4,1),'EXPENDITURE LOG'!$F$5:$F$504,"Church*") | G31: =E31-C31 | H31: =SUMIFS('EXPENDITURE LOG'!$D$5:$D$504,'EXPENDITURE LOG'!$J$5:$J$504,$A31,'EXPENDITURE LOG'!$A$5:$A$504,">="&'SUPPORT PLAN'!$C$4,'EXPENDITURE LOG'!$A$5:$A$504,"<"&EDATE($C$4,1)) | I31: =C31*MAX(0,$F$4) | J31: =H31-I31 | K31: =SUMIFS('EXPENDITURE LOG'!$D$5:$D$504,'EXPENDITURE LOG'!$J$5:$J$504,$A31)
B32: FOOD | C32: =SUM(C33:C38) | D32: =SUM(D33:D38) | E32: =SUM(E33:E38) | F32: =SUM(F33:F38) | G32: =SUM(G33:G38) | H32: =SUM(H33:H38) | I32: =SUM(I33:I38) | J32: =SUM(J33:J38) | K32: =SUM(K33:K38)
A33: =EXPENSES!L31 | B33: =EXPENSES!B31 | C33: =EXPENSES!E31 | D33: =IF(AND($F$4>=1,$F$4<=3),CHOOSE($F$4,'SUPPORT PLAN'!$M33,'SUPPORT PLAN'!$T33,'SUPPORT PLAN'!$AA33),0) | E33: =SUMIFS('EXPENDITURE LOG'!$D$5:$D$504,'EXPENDITURE LOG'!$J$5:$J$504,$A33,'EXPENDITURE LOG'!$A$5:$A$504,">="&$C$4,'EXPENDITURE LOG'!$A$5:$A$504,"<"&EDATE($C$4,1)) | F33: =SUMIFS('EXPENDITURE LOG'!$D$5:$D$504,'EXPENDITURE LOG'!$J$5:$J$504,$A33,'EXPENDITURE LOG'!$A$5:$A$504,">="&$C$4,'EXPENDITURE LOG'!$A$5:$A$504,"<"&EDATE($C$4,1),'EXPENDITURE LOG'!$F$5:$F$504,"Church*") | G33: =E33-C33 | H33: =SUMIFS('EXPENDITURE LOG'!$D$5:$D$504,'EXPENDITURE LOG'!$J$5:$J$504,$A33,'EXPENDITURE LOG'!$A$5:$A$504,">="&'SUPPORT PLAN'!$C$4,'EXPENDITURE LOG'!$A$5:$A$504,"<"&EDATE($C$4,1)) | I33: =C33*MAX(0,$F$4) | J33: =H33-I33 | K33: =SUMIFS('EXPENDITURE LOG'!$D$5:$D$504,'EXPENDITURE LOG'!$J$5:$J$504,$A33)
A34: =EXPENSES!L32 | B34: =EXPENSES!B32 | C34: =EXPENSES!E32 | D34: =IF(AND($F$4>=1,$F$4<=3),CHOOSE($F$4,'SUPPORT PLAN'!$M34,'SUPPORT PLAN'!$T34,'SUPPORT PLAN'!$AA34),0) | E34: =SUMIFS('EXPENDITURE LOG'!$D$5:$D$504,'EXPENDITURE LOG'!$J$5:$J$504,$A34,'EXPENDITURE LOG'!$A$5:$A$504,">="&$C$4,'EXPENDITURE LOG'!$A$5:$A$504,"<"&EDATE($C$4,1)) | F34: =SUMIFS('EXPENDITURE LOG'!$D$5:$D$504,'EXPENDITURE LOG'!$J$5:$J$504,$A34,'EXPENDITURE LOG'!$A$5:$A$504,">="&$C$4,'EXPENDITURE LOG'!$A$5:$A$504,"<"&EDATE($C$4,1),'EXPENDITURE LOG'!$F$5:$F$504,"Church*") | G34: =E34-C34 | H34: =SUMIFS('EXPENDITURE LOG'!$D$5:$D$504,'EXPENDITURE LOG'!$J$5:$J$504,$A34,'EXPENDITURE LOG'!$A$5:$A$504,">="&'SUPPORT PLAN'!$C$4,'EXPENDITURE LOG'!$A$5:$A$504,"<"&EDATE($C$4,1)) | I34: =C34*MAX(0,$F$4) | J34: =H34-I34 | K34: =SUMIFS('EXPENDITURE LOG'!$D$5:$D$504,'EXPENDITURE LOG'!$J$5:$J$504,$A34)
A35: =EXPENSES!L33 | B35: =EXPENSES!B33 | C35: =EXPENSES!E33 | D35: =IF(AND($F$4>=1,$F$4<=3),CHOOSE($F$4,'SUPPORT PLAN'!$M35,'SUPPORT PLAN'!$T35,'SUPPORT PLAN'!$AA35),0) | E35: =SUMIFS('EXPENDITURE LOG'!$D$5:$D$504,'EXPENDITURE LOG'!$J$5:$J$504,$A35,'EXPENDITURE LOG'!$A$5:$A$504,">="&$C$4,'EXPENDITURE LOG'!$A$5:$A$504,"<"&EDATE($C$4,1)) | F35: =SUMIFS('EXPENDITURE LOG'!$D$5:$D$504,'EXPENDITURE LOG'!$J$5:$J$504,$A35,'EXPENDITURE LOG'!$A$5:$A$504,">="&$C$4,'EXPENDITURE LOG'!$A$5:$A$504,"<"&EDATE($C$4,1),'EXPENDITURE LOG'!$F$5:$F$504,"Church*") | G35: =E35-C35 | H35: =SUMIFS('EXPENDITURE LOG'!$D$5:$D$504,'EXPENDITURE LOG'!$J$5:$J$504,$A35,'EXPENDITURE LOG'!$A$5:$A$504,">="&'SUPPORT PLAN'!$C$4,'EXPENDITURE LOG'!$A$5:$A$504,"<"&EDATE($C$4,1)) | I35: =C35*MAX(0,$F$4) | J35: =H35-I35 | K35: =SUMIFS('EXPENDITURE LOG'!$D$5:$D$504,'EXPENDITURE LOG'!$J$5:$J$504,$A35)
